---
title: 자바 - 14 (예외처리)
category:
- Java
tag:
- Java
---

&nbsp;&nbsp;&nbsp;&nbsp;프로그램에서 오류가 발생하는 상황은 두 가지이다.

 - 컴파일 오류 : 프로그램 코드 작성 중 실수로 발생함
 - 런타임 오류(실행 오류) : 실행 중인 프로그램이 의도하지 않은 동작을 하거나 프로그램이 중지됨.

&nbsp;&nbsp;&nbsp;&nbsp;컴파일 오류는 컴파일이 진행되지 않기 때문에 즉각적인 수정이 가능하다. 따라서 컴파일 오류는 서비스가 시작 전에 해결할 수 있다. 하지만 런타임 오류는 실행 중에서 발생하기 때문에 서비스를 제공하는 상황에서 발생하는 경우가 많고, 서비스가 중단될 수 있다.    

&nbsp;&nbsp;&nbsp;&nbsp;이러한 오류를 방지하기 위해서 자바에서는 다양한 예외에 대한 처리 방법을 가지고 있다. 예외 처리의 목적은 프로그램이 비정상 종료되는 것을 방지하기 위해서이다. 그리고 예외가 발생할 시에는 로그 파일을 남겨두어야 한다. 추후에 로그 파일을 분석하여 상황을 파악하고 버그를 수정해야 하기 때문이다.

&nbsp;&nbsp;&nbsp;&nbsp;런타임 오류에는 크게 두 가지로 시스템 오류(error)와 예외(exception)이 있다. 시스템 오류는 사용 가능한 동적 메모리가 없는 경우나, 스택 메모리의 오버플로가 발생한 경우가 있다. 이러한 오류는 프로그램에서 제어할 수가 없다. 하드웨어에 대한 부분인 경우가 많기에 장비를 교체해야만 한다. 
반면, 예외는 프로그램에서 제어할 수 있다. 로드할 파일이 없거나, 네트워크로 데이터를 전송하려는데 연결이 안된 경우, 배열 값을 출력하려고 하는데 배열의 요소가 없는 경우아 그러하다.
런타임 오류를 간략하게 정리하면 다음과 같다.



| 런타임 오류  | 내용 |예시 |
| -------- | -------- | -------- |
| Error(시스템 오류) | 프로그램이 제어할 수 없는 경우 |  Out of memory , Stack of overflow|  
|Exception(예외) |프로그램이 제어할 수 있는 경우 | 로드할 파일이 없음, 인덱스가 없는 배열의 요소를 출력하는 경우|

&nbsp;&nbsp;&nbsp;&nbsp;따라서, 여기서는 프로그램으로 처리할 수 있는 Exception에 대해서 공부하도록 한다.  Exception은 예외 클래스의 최상위 클래스이다.  
&nbsp;&nbsp;&nbsp;&nbsp;Exception 하위 클래스 중 사용 빈도가 높은 클래스는 다음과 같다.

| Exception |   |
|-----------|---|
|   IOException(입출력 예외 )        |   RuntimeException(런타임 예외) |
|   FileNotFountException  | ArithmeticException  |
|  SocketException  |  IndexOutofBoundsException  |

&nbsp;&nbsp;&nbsp;&nbsp;예외를 처리하기 위해서는 try ~ catch 문을 사용한다.

	try{
	//예외가 발생할 수 있는 코드 부분
	} catch (/*처리할 예외 타입*/(exception) e){
	//try에 예외가 발생할 경우 처리할 수행문
	// error log는 e.getMessage()를 통해 호출해서 확인할 수 있다.
	} // catch 구문은 여러 절 나열할 수 있다.

&nbsp;&nbsp;&nbsp;&nbsp;try를 통해서 코드를 실행해보고 예외가 발생하는 그 순간에 catch 구문에서 받아서 프로그램의 중지를 막고 catch 구문부터 프로그램을 실행한다. 즉, catch 구문부터 이후에 작성된 코드들이 순차적으로 실행된다. cath 구문은 여러 절을 나열할 수 있는데, Exception 클래스의 하위 예외 클래스부터 기술해야 한다. 
&nbsp;&nbsp;&nbsp;&nbsp;이러한 try ~ catch 구문을 사용하면 프로그램이 비정상적으로 종료되는 것을 막고 catch문을 통해서 정상적으로 종료되게끔 만든다. 이러한 예외는 try ~ catch 구문을 사용하지 않아도 컴파일과 실행이 가능하다. 가능하지만 에러가 나고 프로그램이 중단된다. 따라서 try ~ catch 구문을 활용해서 프로그램이 중단되지 않고 정상적으로 종료되도록 예외처리를 하는 것이다. 이러한 예외를 자바 가상 머신이 확인해주지 않는다고 해서 unchecked exception이라고 한다.   
&nbsp;&nbsp;&nbsp;&nbsp;반면, 자바 가상 머신이 확인을 하는 checked exception은 컴파일에서 에러가 난다. 대표적으로 FileNotFoundException이 있다. 이 또한 try~catch 구문으로 예외 처리를 할 수 있다. 문법은 위에 기재한 try ~ catch 구문에서 처리할 예외 타입만 변경해서 작성하면 된다. 하지만, 부모 클래스인 Exception을 사용하면 대부분의 예외를 받아낼 수 있다.    
&nbsp;&nbsp;&nbsp;&nbsp;여기서 조금 궁금한게 생겼다. 부모 클래스인 Exception의 자식 클래스가 조금 더 디테일한 예외 클래스인데, 일반적인 상속 관계에서는 자식이 부모의 자원을 전부 사용할 수 있는 걸로 알고 있다. 하지만 자식클래스를 아무거나 집어넣으면 오류가 난다. 자식클래스에서 부모클래스의 자원을 사용하지 못하게 하는 방어기재가 있는 것 같다. 조금 더 공부해봐야 할 주제이다.  

&nbsp;&nbsp;&nbsp;&nbsp;다음으로, try ~ catch ~ finally 구문이 있다. finally의 구문은 예외가 발생하든 발생하지 않든 무조건 수행하는 수행문을 집어넣을 수 있다.

	try{
	//예외가 발생할 수 있는 코드 부분
	} catch /*처리할 예외 타입*/(exception e){
	//try에 예외가 발생할 경우 처리할 수행문
	} finally{
	// 예외에 관계없이 무조건 수행하는 수행문
	}
	
&nbsp;&nbsp;&nbsp;&nbsp;이러한 코드는 예외와 관계없이 무조건 최종적으로 finally을 바라보고 수행한 결과를 도출한다.  
&nbsp;&nbsp;&nbsp;&nbsp;이상으로 기본적인 try ~ catch ~ finally 구문 사용법이다. 여기에 조금 더 내용을 보충하면, return의 위치를 생각해볼 필요가 있다.  
&nbsp;&nbsp;&nbsp;&nbsp;return은 함수에서 반환과 종료를 의미한다. 그렇다면 예외 처리에서도 return을 사용하면 프로그램이 중단될까?   
&nbsp;&nbsp;&nbsp;&nbsp;테스트를 해봤는데, 간단하게 말하면 try든 catch든 finally이든 일단 정상적으로 1회는 진행된다. 예외가 발생하지 않으면 try > finally 로, 예외가 발생하면 try > catch > finally 로 동작한다. 다만, return으로 종료되기 때문에 try 혹은 catch 문에서 return이 존재하면 finally의 구문까지 수행하고 종료된다. 따라서 만약에 finally 뒤에 존재하는 코드가 있는 경우라면 실행되지 않는다.   

	FileInputStream fis = null;

		try
		{
			fis = new FileInputStream("a.txt");
			System.out.println("0");
			return; // try에서 오류가 발생하지 않을 경우는 finally 구문 수행 후 종료
		} // end of try
		catch (Exception e)
		{
			System.out.println(e);
			return; // return이 있을 경우에는 finally 함수를 끝으로 프로그램 종료
			// return 이 없을 경우에는 finally 함수 이후에도 프로그램 실행
		} /* end of catch*/ finally {
			System.out.println("fis >>> :" + fis);
			if (fis != null)
			{
				try
				{
					fis.close();
				}
				catch (IOException e)
				{
					System.out.println("2");
					e.printStackTrace();
				}
			} // end of if
			System.out.println("항상 수행됩니다.");
			//return; >> finally 구문에 return이 존재할 경우, 오류가 발생한다.
		} // end of finally
		System.out.println("여기도 수행 됩니다."); // try or catch 구문에 return이 존재할 경우에 수행 x
		
&nbsp;&nbsp;&nbsp;&nbsp;try랑 catch 의 경우에는 return이 올 수 있다. return이 올 경우에는 finally 구문을 수행하고 finally 구문 뒤에 있는 코드는 수행되지 않는다. 하지만 finally에 return이 올 경우에는  unreachable statement 오류가 발생한다. return 뒤에는 아무것도 올 수 없기 때문이다. 하지만 try나 catch 구문 안에는 return이 올 수 있는걸 보면 try, catch와 finally는 다르다는걸 알 수 있다. 무엇때문에 다른지는 모르겠지만. 왜 다른 건지는 좀 더 공부가 필요할 것 같다.  
&nbsp;&nbsp;&nbsp;&nbsp;이상은 예외를 처리하는 방법에 대해서 작성했다. 예외를 처리할 수도 있지만, 예외 처리를 호출한 함수에게로 미룰 수도 있다. class를 작성할 때 throws Exception을 통해서 예외를 미룬다.  예외를 미루면 호출하는 메서드에서 예외를 처리해야 한다. 
&nbsp;&nbsp;&nbsp;&nbsp;이는 다른 여러 코드에서 호출되어 사용하는 경우에는 상황에 따라서 다른 예외가 발생할 수 있으니 메서드를 호출하는 부분에서 예외처리를 하도록 미루는 것이 합리적이다. 일반적으로 throws는 main()까지 미룬 다음에 main()에서 직접 예외처리하도록 구현한다. main()에서도 미루면 init으로 간다고 하는데 미루지말고 main()에서는 처리해야 한다.    
&nbsp;&nbsp;&nbsp;&nbsp;예외는 필요하면 사용자가 직접 만들 수도 있다. Exception 을 상속받아서  부모 클래스의 생성자롤 호출하고 메시지를 남기면 쉽게 사용자 정의 예외 클래스를 만들 수 있다.

	// 사용자 정의 예외 클래스 
	class IDFormatException extends Exception
	{
		// 생성자 
		public IDFormatException(String s){
			super(s); // 부모 클래스의 생성자 호출하고 메시지를 s로 생성한다.
		}
	}
	
	class IDFormatTest
	{
		private String userID;

	public String getUserID(){
		return userID;
	}

	public void setUserID(String userID) throws IDFormatException {
		if (userID == null)
		{ // new를 통해 예외를 만든 후 참조변수를 throw 키워드로 예외를 발생시킨다.
			IDFormatException ide = new IDFormatException("아이디는 null일 수 없습니다.");
			throw ide;
		}
		else if (userID.length() < 8 || userID.length() > 20)
		{
			throw new IDFormatException("아이디은 8 ~ 20자 이하 입니다.");
		}
		this.userID = userID;
	}
